{
  "nbformat": 4,
  "nbformat_minor": 0,
  "metadata": {
    "colab": {
      "provenance": [],
      "gpuType": "T4",
      "mount_file_id": "1OTecv9w8v0QoCRuOo5OA8Bv45cAguRJs",
      "authorship_tag": "ABX9TyPVjFTj5xpDJsCHW/quuL38",
      "include_colab_link": true
    },
    "kernelspec": {
      "name": "python3",
      "display_name": "Python 3"
    },
    "language_info": {
      "name": "python"
    },
    "accelerator": "GPU"
  },
  "cells": [
    {
      "cell_type": "markdown",
      "metadata": {
        "id": "view-in-github",
        "colab_type": "text"
      },
      "source": [
        "<a href=\"https://colab.research.google.com/github/Cpalm03/Big-Data-Analytics/blob/main/ICP7.ipynb\" target=\"_parent\"><img src=\"https://colab.research.google.com/assets/colab-badge.svg\" alt=\"Open In Colab\"/></a>"
      ]
    },
    {
      "cell_type": "code",
      "source": [
        "!pip install scikeras"
      ],
      "metadata": {
        "colab": {
          "base_uri": "https://localhost:8080/"
        },
        "id": "D5gF4QA72LP4",
        "outputId": "824c69e0-ca61-4d5d-dc3a-afdae674d164"
      },
      "execution_count": null,
      "outputs": [
        {
          "output_type": "stream",
          "name": "stdout",
          "text": [
            "Collecting scikeras\n",
            "  Downloading scikeras-0.13.0-py3-none-any.whl.metadata (3.1 kB)\n",
            "Requirement already satisfied: keras>=3.2.0 in /usr/local/lib/python3.10/dist-packages (from scikeras) (3.4.1)\n",
            "Requirement already satisfied: scikit-learn>=1.4.2 in /usr/local/lib/python3.10/dist-packages (from scikeras) (1.5.2)\n",
            "Requirement already satisfied: absl-py in /usr/local/lib/python3.10/dist-packages (from keras>=3.2.0->scikeras) (1.4.0)\n",
            "Requirement already satisfied: numpy in /usr/local/lib/python3.10/dist-packages (from keras>=3.2.0->scikeras) (1.26.4)\n",
            "Requirement already satisfied: rich in /usr/local/lib/python3.10/dist-packages (from keras>=3.2.0->scikeras) (13.9.3)\n",
            "Requirement already satisfied: namex in /usr/local/lib/python3.10/dist-packages (from keras>=3.2.0->scikeras) (0.0.8)\n",
            "Requirement already satisfied: h5py in /usr/local/lib/python3.10/dist-packages (from keras>=3.2.0->scikeras) (3.11.0)\n",
            "Requirement already satisfied: optree in /usr/local/lib/python3.10/dist-packages (from keras>=3.2.0->scikeras) (0.13.0)\n",
            "Requirement already satisfied: ml-dtypes in /usr/local/lib/python3.10/dist-packages (from keras>=3.2.0->scikeras) (0.4.1)\n",
            "Requirement already satisfied: packaging in /usr/local/lib/python3.10/dist-packages (from keras>=3.2.0->scikeras) (24.1)\n",
            "Requirement already satisfied: scipy>=1.6.0 in /usr/local/lib/python3.10/dist-packages (from scikit-learn>=1.4.2->scikeras) (1.13.1)\n",
            "Requirement already satisfied: joblib>=1.2.0 in /usr/local/lib/python3.10/dist-packages (from scikit-learn>=1.4.2->scikeras) (1.4.2)\n",
            "Requirement already satisfied: threadpoolctl>=3.1.0 in /usr/local/lib/python3.10/dist-packages (from scikit-learn>=1.4.2->scikeras) (3.5.0)\n",
            "Requirement already satisfied: typing-extensions>=4.5.0 in /usr/local/lib/python3.10/dist-packages (from optree->keras>=3.2.0->scikeras) (4.12.2)\n",
            "Requirement already satisfied: markdown-it-py>=2.2.0 in /usr/local/lib/python3.10/dist-packages (from rich->keras>=3.2.0->scikeras) (3.0.0)\n",
            "Requirement already satisfied: pygments<3.0.0,>=2.13.0 in /usr/local/lib/python3.10/dist-packages (from rich->keras>=3.2.0->scikeras) (2.18.0)\n",
            "Requirement already satisfied: mdurl~=0.1 in /usr/local/lib/python3.10/dist-packages (from markdown-it-py>=2.2.0->rich->keras>=3.2.0->scikeras) (0.1.2)\n",
            "Downloading scikeras-0.13.0-py3-none-any.whl (26 kB)\n",
            "Installing collected packages: scikeras\n",
            "Successfully installed scikeras-0.13.0\n"
          ]
        }
      ]
    },
    {
      "cell_type": "code",
      "execution_count": null,
      "metadata": {
        "colab": {
          "base_uri": "https://localhost:8080/",
          "height": 1000
        },
        "id": "8938Iv1P2UQJ",
        "outputId": "7857e366-22c6-4dd2-ddea-d852ddabcb9a"
      },
      "outputs": [
        {
          "output_type": "stream",
          "name": "stderr",
          "text": [
            "<ipython-input-43-3440bb3762df>:23: FutureWarning: Series.__getitem__ treating keys as positions is deprecated. In a future version, integer keys will always be treated as labels (consistent with DataFrame behavior). To access a value by position, use `ser.iloc[pos]`\n",
            "  row[0] = row[0].replace('rt', ' ')\n",
            "<ipython-input-43-3440bb3762df>:23: FutureWarning: Series.__setitem__ treating keys as positions is deprecated. In a future version, integer keys will always be treated as labels (consistent with DataFrame behavior). To set a value by position, use `ser.iloc[pos] = value`\n",
            "  row[0] = row[0].replace('rt', ' ')\n"
          ]
        },
        {
          "output_type": "stream",
          "name": "stdout",
          "text": [
            "Fitting 3 folds for each of 9 candidates, totalling 27 fits\n"
          ]
        },
        {
          "output_type": "stream",
          "name": "stderr",
          "text": [
            "/usr/local/lib/python3.10/dist-packages/scikeras/wrappers.py:925: UserWarning: ``build_fn`` will be renamed to ``model`` in a future release, at which point use of ``build_fn`` will raise an Error instead.\n",
            "  X, y = self._initialize(X, y)\n",
            "/usr/local/lib/python3.10/dist-packages/keras/src/layers/core/embedding.py:90: UserWarning: Argument `input_length` is deprecated. Just remove it.\n",
            "  warnings.warn(\n",
            "/usr/local/lib/python3.10/dist-packages/scikeras/wrappers.py:925: UserWarning: ``build_fn`` will be renamed to ``model`` in a future release, at which point use of ``build_fn`` will raise an Error instead.\n",
            "  X, y = self._initialize(X, y)\n",
            "/usr/local/lib/python3.10/dist-packages/keras/src/layers/core/embedding.py:90: UserWarning: Argument `input_length` is deprecated. Just remove it.\n",
            "  warnings.warn(\n",
            "/usr/local/lib/python3.10/dist-packages/scikeras/wrappers.py:925: UserWarning: ``build_fn`` will be renamed to ``model`` in a future release, at which point use of ``build_fn`` will raise an Error instead.\n",
            "  X, y = self._initialize(X, y)\n",
            "/usr/local/lib/python3.10/dist-packages/keras/src/layers/core/embedding.py:90: UserWarning: Argument `input_length` is deprecated. Just remove it.\n",
            "  warnings.warn(\n",
            "/usr/local/lib/python3.10/dist-packages/scikeras/wrappers.py:925: UserWarning: ``build_fn`` will be renamed to ``model`` in a future release, at which point use of ``build_fn`` will raise an Error instead.\n",
            "  X, y = self._initialize(X, y)\n",
            "/usr/local/lib/python3.10/dist-packages/keras/src/layers/core/embedding.py:90: UserWarning: Argument `input_length` is deprecated. Just remove it.\n",
            "  warnings.warn(\n",
            "/usr/local/lib/python3.10/dist-packages/scikeras/wrappers.py:925: UserWarning: ``build_fn`` will be renamed to ``model`` in a future release, at which point use of ``build_fn`` will raise an Error instead.\n",
            "  X, y = self._initialize(X, y)\n",
            "/usr/local/lib/python3.10/dist-packages/keras/src/layers/core/embedding.py:90: UserWarning: Argument `input_length` is deprecated. Just remove it.\n",
            "  warnings.warn(\n",
            "/usr/local/lib/python3.10/dist-packages/scikeras/wrappers.py:925: UserWarning: ``build_fn`` will be renamed to ``model`` in a future release, at which point use of ``build_fn`` will raise an Error instead.\n",
            "  X, y = self._initialize(X, y)\n",
            "/usr/local/lib/python3.10/dist-packages/keras/src/layers/core/embedding.py:90: UserWarning: Argument `input_length` is deprecated. Just remove it.\n",
            "  warnings.warn(\n",
            "/usr/local/lib/python3.10/dist-packages/scikeras/wrappers.py:925: UserWarning: ``build_fn`` will be renamed to ``model`` in a future release, at which point use of ``build_fn`` will raise an Error instead.\n",
            "  X, y = self._initialize(X, y)\n",
            "/usr/local/lib/python3.10/dist-packages/keras/src/layers/core/embedding.py:90: UserWarning: Argument `input_length` is deprecated. Just remove it.\n",
            "  warnings.warn(\n",
            "/usr/local/lib/python3.10/dist-packages/scikeras/wrappers.py:925: UserWarning: ``build_fn`` will be renamed to ``model`` in a future release, at which point use of ``build_fn`` will raise an Error instead.\n",
            "  X, y = self._initialize(X, y)\n",
            "/usr/local/lib/python3.10/dist-packages/keras/src/layers/core/embedding.py:90: UserWarning: Argument `input_length` is deprecated. Just remove it.\n",
            "  warnings.warn(\n",
            "/usr/local/lib/python3.10/dist-packages/scikeras/wrappers.py:925: UserWarning: ``build_fn`` will be renamed to ``model`` in a future release, at which point use of ``build_fn`` will raise an Error instead.\n",
            "  X, y = self._initialize(X, y)\n",
            "/usr/local/lib/python3.10/dist-packages/keras/src/layers/core/embedding.py:90: UserWarning: Argument `input_length` is deprecated. Just remove it.\n",
            "  warnings.warn(\n",
            "/usr/local/lib/python3.10/dist-packages/scikeras/wrappers.py:925: UserWarning: ``build_fn`` will be renamed to ``model`` in a future release, at which point use of ``build_fn`` will raise an Error instead.\n",
            "  X, y = self._initialize(X, y)\n",
            "/usr/local/lib/python3.10/dist-packages/keras/src/layers/core/embedding.py:90: UserWarning: Argument `input_length` is deprecated. Just remove it.\n",
            "  warnings.warn(\n",
            "/usr/local/lib/python3.10/dist-packages/scikeras/wrappers.py:925: UserWarning: ``build_fn`` will be renamed to ``model`` in a future release, at which point use of ``build_fn`` will raise an Error instead.\n",
            "  X, y = self._initialize(X, y)\n",
            "/usr/local/lib/python3.10/dist-packages/keras/src/layers/core/embedding.py:90: UserWarning: Argument `input_length` is deprecated. Just remove it.\n",
            "  warnings.warn(\n",
            "/usr/local/lib/python3.10/dist-packages/scikeras/wrappers.py:925: UserWarning: ``build_fn`` will be renamed to ``model`` in a future release, at which point use of ``build_fn`` will raise an Error instead.\n",
            "  X, y = self._initialize(X, y)\n",
            "/usr/local/lib/python3.10/dist-packages/keras/src/layers/core/embedding.py:90: UserWarning: Argument `input_length` is deprecated. Just remove it.\n",
            "  warnings.warn(\n",
            "/usr/local/lib/python3.10/dist-packages/scikeras/wrappers.py:925: UserWarning: ``build_fn`` will be renamed to ``model`` in a future release, at which point use of ``build_fn`` will raise an Error instead.\n",
            "  X, y = self._initialize(X, y)\n",
            "/usr/local/lib/python3.10/dist-packages/keras/src/layers/core/embedding.py:90: UserWarning: Argument `input_length` is deprecated. Just remove it.\n",
            "  warnings.warn(\n",
            "/usr/local/lib/python3.10/dist-packages/scikeras/wrappers.py:925: UserWarning: ``build_fn`` will be renamed to ``model`` in a future release, at which point use of ``build_fn`` will raise an Error instead.\n",
            "  X, y = self._initialize(X, y)\n",
            "/usr/local/lib/python3.10/dist-packages/keras/src/layers/core/embedding.py:90: UserWarning: Argument `input_length` is deprecated. Just remove it.\n",
            "  warnings.warn(\n",
            "/usr/local/lib/python3.10/dist-packages/scikeras/wrappers.py:925: UserWarning: ``build_fn`` will be renamed to ``model`` in a future release, at which point use of ``build_fn`` will raise an Error instead.\n",
            "  X, y = self._initialize(X, y)\n",
            "/usr/local/lib/python3.10/dist-packages/keras/src/layers/core/embedding.py:90: UserWarning: Argument `input_length` is deprecated. Just remove it.\n",
            "  warnings.warn(\n",
            "/usr/local/lib/python3.10/dist-packages/scikeras/wrappers.py:925: UserWarning: ``build_fn`` will be renamed to ``model`` in a future release, at which point use of ``build_fn`` will raise an Error instead.\n",
            "  X, y = self._initialize(X, y)\n",
            "/usr/local/lib/python3.10/dist-packages/keras/src/layers/core/embedding.py:90: UserWarning: Argument `input_length` is deprecated. Just remove it.\n",
            "  warnings.warn(\n",
            "/usr/local/lib/python3.10/dist-packages/scikeras/wrappers.py:925: UserWarning: ``build_fn`` will be renamed to ``model`` in a future release, at which point use of ``build_fn`` will raise an Error instead.\n",
            "  X, y = self._initialize(X, y)\n",
            "/usr/local/lib/python3.10/dist-packages/keras/src/layers/core/embedding.py:90: UserWarning: Argument `input_length` is deprecated. Just remove it.\n",
            "  warnings.warn(\n",
            "/usr/local/lib/python3.10/dist-packages/scikeras/wrappers.py:925: UserWarning: ``build_fn`` will be renamed to ``model`` in a future release, at which point use of ``build_fn`` will raise an Error instead.\n",
            "  X, y = self._initialize(X, y)\n",
            "/usr/local/lib/python3.10/dist-packages/keras/src/layers/core/embedding.py:90: UserWarning: Argument `input_length` is deprecated. Just remove it.\n",
            "  warnings.warn(\n",
            "/usr/local/lib/python3.10/dist-packages/scikeras/wrappers.py:925: UserWarning: ``build_fn`` will be renamed to ``model`` in a future release, at which point use of ``build_fn`` will raise an Error instead.\n",
            "  X, y = self._initialize(X, y)\n",
            "/usr/local/lib/python3.10/dist-packages/keras/src/layers/core/embedding.py:90: UserWarning: Argument `input_length` is deprecated. Just remove it.\n",
            "  warnings.warn(\n",
            "/usr/local/lib/python3.10/dist-packages/scikeras/wrappers.py:925: UserWarning: ``build_fn`` will be renamed to ``model`` in a future release, at which point use of ``build_fn`` will raise an Error instead.\n",
            "  X, y = self._initialize(X, y)\n",
            "/usr/local/lib/python3.10/dist-packages/keras/src/layers/core/embedding.py:90: UserWarning: Argument `input_length` is deprecated. Just remove it.\n",
            "  warnings.warn(\n",
            "/usr/local/lib/python3.10/dist-packages/scikeras/wrappers.py:925: UserWarning: ``build_fn`` will be renamed to ``model`` in a future release, at which point use of ``build_fn`` will raise an Error instead.\n",
            "  X, y = self._initialize(X, y)\n",
            "/usr/local/lib/python3.10/dist-packages/keras/src/layers/core/embedding.py:90: UserWarning: Argument `input_length` is deprecated. Just remove it.\n",
            "  warnings.warn(\n",
            "/usr/local/lib/python3.10/dist-packages/scikeras/wrappers.py:925: UserWarning: ``build_fn`` will be renamed to ``model`` in a future release, at which point use of ``build_fn`` will raise an Error instead.\n",
            "  X, y = self._initialize(X, y)\n",
            "/usr/local/lib/python3.10/dist-packages/keras/src/layers/core/embedding.py:90: UserWarning: Argument `input_length` is deprecated. Just remove it.\n",
            "  warnings.warn(\n",
            "/usr/local/lib/python3.10/dist-packages/scikeras/wrappers.py:925: UserWarning: ``build_fn`` will be renamed to ``model`` in a future release, at which point use of ``build_fn`` will raise an Error instead.\n",
            "  X, y = self._initialize(X, y)\n",
            "/usr/local/lib/python3.10/dist-packages/keras/src/layers/core/embedding.py:90: UserWarning: Argument `input_length` is deprecated. Just remove it.\n",
            "  warnings.warn(\n",
            "/usr/local/lib/python3.10/dist-packages/scikeras/wrappers.py:925: UserWarning: ``build_fn`` will be renamed to ``model`` in a future release, at which point use of ``build_fn`` will raise an Error instead.\n",
            "  X, y = self._initialize(X, y)\n",
            "/usr/local/lib/python3.10/dist-packages/keras/src/layers/core/embedding.py:90: UserWarning: Argument `input_length` is deprecated. Just remove it.\n",
            "  warnings.warn(\n",
            "/usr/local/lib/python3.10/dist-packages/scikeras/wrappers.py:925: UserWarning: ``build_fn`` will be renamed to ``model`` in a future release, at which point use of ``build_fn`` will raise an Error instead.\n",
            "  X, y = self._initialize(X, y)\n",
            "/usr/local/lib/python3.10/dist-packages/keras/src/layers/core/embedding.py:90: UserWarning: Argument `input_length` is deprecated. Just remove it.\n",
            "  warnings.warn(\n",
            "/usr/local/lib/python3.10/dist-packages/scikeras/wrappers.py:925: UserWarning: ``build_fn`` will be renamed to ``model`` in a future release, at which point use of ``build_fn`` will raise an Error instead.\n",
            "  X, y = self._initialize(X, y)\n",
            "/usr/local/lib/python3.10/dist-packages/keras/src/layers/core/embedding.py:90: UserWarning: Argument `input_length` is deprecated. Just remove it.\n",
            "  warnings.warn(\n",
            "/usr/local/lib/python3.10/dist-packages/scikeras/wrappers.py:925: UserWarning: ``build_fn`` will be renamed to ``model`` in a future release, at which point use of ``build_fn`` will raise an Error instead.\n",
            "  X, y = self._initialize(X, y)\n",
            "/usr/local/lib/python3.10/dist-packages/keras/src/layers/core/embedding.py:90: UserWarning: Argument `input_length` is deprecated. Just remove it.\n",
            "  warnings.warn(\n"
          ]
        },
        {
          "output_type": "error",
          "ename": "ValueError",
          "evalue": "\nAll the 27 fits failed.\nIt is very likely that your model is misconfigured.\nYou can try to debug the error by setting error_score='raise'.\n\nBelow are more details about the failures:\n--------------------------------------------------------------------------------\n1 fits failed with the following error:\nTraceback (most recent call last):\n  File \"/usr/local/lib/python3.10/dist-packages/sklearn/model_selection/_validation.py\", line 888, in _fit_and_score\n    estimator.fit(X_train, y_train, **fit_params)\n  File \"/usr/local/lib/python3.10/dist-packages/scikeras/wrappers.py\", line 1501, in fit\n    super().fit(X=X, y=y, sample_weight=sample_weight, **kwargs)\n  File \"/usr/local/lib/python3.10/dist-packages/scikeras/wrappers.py\", line 770, in fit\n    self._fit(\n  File \"/usr/local/lib/python3.10/dist-packages/scikeras/wrappers.py\", line 936, in _fit\n    self._check_model_compatibility(y)\n  File \"/usr/local/lib/python3.10/dist-packages/scikeras/wrappers.py\", line 559, in _check_model_compatibility\n    if self.n_outputs_expected_ != len(self.model_.outputs):\n  File \"/usr/local/lib/python3.10/dist-packages/keras/src/models/sequential.py\", line 292, in outputs\n    raise ValueError(\nValueError: Sequential model 'sequential_120' has no defined outputs yet.\n\n--------------------------------------------------------------------------------\n1 fits failed with the following error:\nTraceback (most recent call last):\n  File \"/usr/local/lib/python3.10/dist-packages/sklearn/model_selection/_validation.py\", line 888, in _fit_and_score\n    estimator.fit(X_train, y_train, **fit_params)\n  File \"/usr/local/lib/python3.10/dist-packages/scikeras/wrappers.py\", line 1501, in fit\n    super().fit(X=X, y=y, sample_weight=sample_weight, **kwargs)\n  File \"/usr/local/lib/python3.10/dist-packages/scikeras/wrappers.py\", line 770, in fit\n    self._fit(\n  File \"/usr/local/lib/python3.10/dist-packages/scikeras/wrappers.py\", line 936, in _fit\n    self._check_model_compatibility(y)\n  File \"/usr/local/lib/python3.10/dist-packages/scikeras/wrappers.py\", line 559, in _check_model_compatibility\n    if self.n_outputs_expected_ != len(self.model_.outputs):\n  File \"/usr/local/lib/python3.10/dist-packages/keras/src/models/sequential.py\", line 292, in outputs\n    raise ValueError(\nValueError: Sequential model 'sequential_121' has no defined outputs yet.\n\n--------------------------------------------------------------------------------\n1 fits failed with the following error:\nTraceback (most recent call last):\n  File \"/usr/local/lib/python3.10/dist-packages/sklearn/model_selection/_validation.py\", line 888, in _fit_and_score\n    estimator.fit(X_train, y_train, **fit_params)\n  File \"/usr/local/lib/python3.10/dist-packages/scikeras/wrappers.py\", line 1501, in fit\n    super().fit(X=X, y=y, sample_weight=sample_weight, **kwargs)\n  File \"/usr/local/lib/python3.10/dist-packages/scikeras/wrappers.py\", line 770, in fit\n    self._fit(\n  File \"/usr/local/lib/python3.10/dist-packages/scikeras/wrappers.py\", line 936, in _fit\n    self._check_model_compatibility(y)\n  File \"/usr/local/lib/python3.10/dist-packages/scikeras/wrappers.py\", line 559, in _check_model_compatibility\n    if self.n_outputs_expected_ != len(self.model_.outputs):\n  File \"/usr/local/lib/python3.10/dist-packages/keras/src/models/sequential.py\", line 292, in outputs\n    raise ValueError(\nValueError: Sequential model 'sequential_122' has no defined outputs yet.\n\n--------------------------------------------------------------------------------\n1 fits failed with the following error:\nTraceback (most recent call last):\n  File \"/usr/local/lib/python3.10/dist-packages/sklearn/model_selection/_validation.py\", line 888, in _fit_and_score\n    estimator.fit(X_train, y_train, **fit_params)\n  File \"/usr/local/lib/python3.10/dist-packages/scikeras/wrappers.py\", line 1501, in fit\n    super().fit(X=X, y=y, sample_weight=sample_weight, **kwargs)\n  File \"/usr/local/lib/python3.10/dist-packages/scikeras/wrappers.py\", line 770, in fit\n    self._fit(\n  File \"/usr/local/lib/python3.10/dist-packages/scikeras/wrappers.py\", line 936, in _fit\n    self._check_model_compatibility(y)\n  File \"/usr/local/lib/python3.10/dist-packages/scikeras/wrappers.py\", line 559, in _check_model_compatibility\n    if self.n_outputs_expected_ != len(self.model_.outputs):\n  File \"/usr/local/lib/python3.10/dist-packages/keras/src/models/sequential.py\", line 292, in outputs\n    raise ValueError(\nValueError: Sequential model 'sequential_123' has no defined outputs yet.\n\n--------------------------------------------------------------------------------\n1 fits failed with the following error:\nTraceback (most recent call last):\n  File \"/usr/local/lib/python3.10/dist-packages/sklearn/model_selection/_validation.py\", line 888, in _fit_and_score\n    estimator.fit(X_train, y_train, **fit_params)\n  File \"/usr/local/lib/python3.10/dist-packages/scikeras/wrappers.py\", line 1501, in fit\n    super().fit(X=X, y=y, sample_weight=sample_weight, **kwargs)\n  File \"/usr/local/lib/python3.10/dist-packages/scikeras/wrappers.py\", line 770, in fit\n    self._fit(\n  File \"/usr/local/lib/python3.10/dist-packages/scikeras/wrappers.py\", line 936, in _fit\n    self._check_model_compatibility(y)\n  File \"/usr/local/lib/python3.10/dist-packages/scikeras/wrappers.py\", line 559, in _check_model_compatibility\n    if self.n_outputs_expected_ != len(self.model_.outputs):\n  File \"/usr/local/lib/python3.10/dist-packages/keras/src/models/sequential.py\", line 292, in outputs\n    raise ValueError(\nValueError: Sequential model 'sequential_124' has no defined outputs yet.\n\n--------------------------------------------------------------------------------\n1 fits failed with the following error:\nTraceback (most recent call last):\n  File \"/usr/local/lib/python3.10/dist-packages/sklearn/model_selection/_validation.py\", line 888, in _fit_and_score\n    estimator.fit(X_train, y_train, **fit_params)\n  File \"/usr/local/lib/python3.10/dist-packages/scikeras/wrappers.py\", line 1501, in fit\n    super().fit(X=X, y=y, sample_weight=sample_weight, **kwargs)\n  File \"/usr/local/lib/python3.10/dist-packages/scikeras/wrappers.py\", line 770, in fit\n    self._fit(\n  File \"/usr/local/lib/python3.10/dist-packages/scikeras/wrappers.py\", line 936, in _fit\n    self._check_model_compatibility(y)\n  File \"/usr/local/lib/python3.10/dist-packages/scikeras/wrappers.py\", line 559, in _check_model_compatibility\n    if self.n_outputs_expected_ != len(self.model_.outputs):\n  File \"/usr/local/lib/python3.10/dist-packages/keras/src/models/sequential.py\", line 292, in outputs\n    raise ValueError(\nValueError: Sequential model 'sequential_125' has no defined outputs yet.\n\n--------------------------------------------------------------------------------\n1 fits failed with the following error:\nTraceback (most recent call last):\n  File \"/usr/local/lib/python3.10/dist-packages/sklearn/model_selection/_validation.py\", line 888, in _fit_and_score\n    estimator.fit(X_train, y_train, **fit_params)\n  File \"/usr/local/lib/python3.10/dist-packages/scikeras/wrappers.py\", line 1501, in fit\n    super().fit(X=X, y=y, sample_weight=sample_weight, **kwargs)\n  File \"/usr/local/lib/python3.10/dist-packages/scikeras/wrappers.py\", line 770, in fit\n    self._fit(\n  File \"/usr/local/lib/python3.10/dist-packages/scikeras/wrappers.py\", line 936, in _fit\n    self._check_model_compatibility(y)\n  File \"/usr/local/lib/python3.10/dist-packages/scikeras/wrappers.py\", line 559, in _check_model_compatibility\n    if self.n_outputs_expected_ != len(self.model_.outputs):\n  File \"/usr/local/lib/python3.10/dist-packages/keras/src/models/sequential.py\", line 292, in outputs\n    raise ValueError(\nValueError: Sequential model 'sequential_126' has no defined outputs yet.\n\n--------------------------------------------------------------------------------\n1 fits failed with the following error:\nTraceback (most recent call last):\n  File \"/usr/local/lib/python3.10/dist-packages/sklearn/model_selection/_validation.py\", line 888, in _fit_and_score\n    estimator.fit(X_train, y_train, **fit_params)\n  File \"/usr/local/lib/python3.10/dist-packages/scikeras/wrappers.py\", line 1501, in fit\n    super().fit(X=X, y=y, sample_weight=sample_weight, **kwargs)\n  File \"/usr/local/lib/python3.10/dist-packages/scikeras/wrappers.py\", line 770, in fit\n    self._fit(\n  File \"/usr/local/lib/python3.10/dist-packages/scikeras/wrappers.py\", line 936, in _fit\n    self._check_model_compatibility(y)\n  File \"/usr/local/lib/python3.10/dist-packages/scikeras/wrappers.py\", line 559, in _check_model_compatibility\n    if self.n_outputs_expected_ != len(self.model_.outputs):\n  File \"/usr/local/lib/python3.10/dist-packages/keras/src/models/sequential.py\", line 292, in outputs\n    raise ValueError(\nValueError: Sequential model 'sequential_127' has no defined outputs yet.\n\n--------------------------------------------------------------------------------\n1 fits failed with the following error:\nTraceback (most recent call last):\n  File \"/usr/local/lib/python3.10/dist-packages/sklearn/model_selection/_validation.py\", line 888, in _fit_and_score\n    estimator.fit(X_train, y_train, **fit_params)\n  File \"/usr/local/lib/python3.10/dist-packages/scikeras/wrappers.py\", line 1501, in fit\n    super().fit(X=X, y=y, sample_weight=sample_weight, **kwargs)\n  File \"/usr/local/lib/python3.10/dist-packages/scikeras/wrappers.py\", line 770, in fit\n    self._fit(\n  File \"/usr/local/lib/python3.10/dist-packages/scikeras/wrappers.py\", line 936, in _fit\n    self._check_model_compatibility(y)\n  File \"/usr/local/lib/python3.10/dist-packages/scikeras/wrappers.py\", line 559, in _check_model_compatibility\n    if self.n_outputs_expected_ != len(self.model_.outputs):\n  File \"/usr/local/lib/python3.10/dist-packages/keras/src/models/sequential.py\", line 292, in outputs\n    raise ValueError(\nValueError: Sequential model 'sequential_128' has no defined outputs yet.\n\n--------------------------------------------------------------------------------\n1 fits failed with the following error:\nTraceback (most recent call last):\n  File \"/usr/local/lib/python3.10/dist-packages/sklearn/model_selection/_validation.py\", line 888, in _fit_and_score\n    estimator.fit(X_train, y_train, **fit_params)\n  File \"/usr/local/lib/python3.10/dist-packages/scikeras/wrappers.py\", line 1501, in fit\n    super().fit(X=X, y=y, sample_weight=sample_weight, **kwargs)\n  File \"/usr/local/lib/python3.10/dist-packages/scikeras/wrappers.py\", line 770, in fit\n    self._fit(\n  File \"/usr/local/lib/python3.10/dist-packages/scikeras/wrappers.py\", line 936, in _fit\n    self._check_model_compatibility(y)\n  File \"/usr/local/lib/python3.10/dist-packages/scikeras/wrappers.py\", line 559, in _check_model_compatibility\n    if self.n_outputs_expected_ != len(self.model_.outputs):\n  File \"/usr/local/lib/python3.10/dist-packages/keras/src/models/sequential.py\", line 292, in outputs\n    raise ValueError(\nValueError: Sequential model 'sequential_129' has no defined outputs yet.\n\n--------------------------------------------------------------------------------\n1 fits failed with the following error:\nTraceback (most recent call last):\n  File \"/usr/local/lib/python3.10/dist-packages/sklearn/model_selection/_validation.py\", line 888, in _fit_and_score\n    estimator.fit(X_train, y_train, **fit_params)\n  File \"/usr/local/lib/python3.10/dist-packages/scikeras/wrappers.py\", line 1501, in fit\n    super().fit(X=X, y=y, sample_weight=sample_weight, **kwargs)\n  File \"/usr/local/lib/python3.10/dist-packages/scikeras/wrappers.py\", line 770, in fit\n    self._fit(\n  File \"/usr/local/lib/python3.10/dist-packages/scikeras/wrappers.py\", line 936, in _fit\n    self._check_model_compatibility(y)\n  File \"/usr/local/lib/python3.10/dist-packages/scikeras/wrappers.py\", line 559, in _check_model_compatibility\n    if self.n_outputs_expected_ != len(self.model_.outputs):\n  File \"/usr/local/lib/python3.10/dist-packages/keras/src/models/sequential.py\", line 292, in outputs\n    raise ValueError(\nValueError: Sequential model 'sequential_130' has no defined outputs yet.\n\n--------------------------------------------------------------------------------\n1 fits failed with the following error:\nTraceback (most recent call last):\n  File \"/usr/local/lib/python3.10/dist-packages/sklearn/model_selection/_validation.py\", line 888, in _fit_and_score\n    estimator.fit(X_train, y_train, **fit_params)\n  File \"/usr/local/lib/python3.10/dist-packages/scikeras/wrappers.py\", line 1501, in fit\n    super().fit(X=X, y=y, sample_weight=sample_weight, **kwargs)\n  File \"/usr/local/lib/python3.10/dist-packages/scikeras/wrappers.py\", line 770, in fit\n    self._fit(\n  File \"/usr/local/lib/python3.10/dist-packages/scikeras/wrappers.py\", line 936, in _fit\n    self._check_model_compatibility(y)\n  File \"/usr/local/lib/python3.10/dist-packages/scikeras/wrappers.py\", line 559, in _check_model_compatibility\n    if self.n_outputs_expected_ != len(self.model_.outputs):\n  File \"/usr/local/lib/python3.10/dist-packages/keras/src/models/sequential.py\", line 292, in outputs\n    raise ValueError(\nValueError: Sequential model 'sequential_131' has no defined outputs yet.\n\n--------------------------------------------------------------------------------\n1 fits failed with the following error:\nTraceback (most recent call last):\n  File \"/usr/local/lib/python3.10/dist-packages/sklearn/model_selection/_validation.py\", line 888, in _fit_and_score\n    estimator.fit(X_train, y_train, **fit_params)\n  File \"/usr/local/lib/python3.10/dist-packages/scikeras/wrappers.py\", line 1501, in fit\n    super().fit(X=X, y=y, sample_weight=sample_weight, **kwargs)\n  File \"/usr/local/lib/python3.10/dist-packages/scikeras/wrappers.py\", line 770, in fit\n    self._fit(\n  File \"/usr/local/lib/python3.10/dist-packages/scikeras/wrappers.py\", line 936, in _fit\n    self._check_model_compatibility(y)\n  File \"/usr/local/lib/python3.10/dist-packages/scikeras/wrappers.py\", line 559, in _check_model_compatibility\n    if self.n_outputs_expected_ != len(self.model_.outputs):\n  File \"/usr/local/lib/python3.10/dist-packages/keras/src/models/sequential.py\", line 292, in outputs\n    raise ValueError(\nValueError: Sequential model 'sequential_132' has no defined outputs yet.\n\n--------------------------------------------------------------------------------\n1 fits failed with the following error:\nTraceback (most recent call last):\n  File \"/usr/local/lib/python3.10/dist-packages/sklearn/model_selection/_validation.py\", line 888, in _fit_and_score\n    estimator.fit(X_train, y_train, **fit_params)\n  File \"/usr/local/lib/python3.10/dist-packages/scikeras/wrappers.py\", line 1501, in fit\n    super().fit(X=X, y=y, sample_weight=sample_weight, **kwargs)\n  File \"/usr/local/lib/python3.10/dist-packages/scikeras/wrappers.py\", line 770, in fit\n    self._fit(\n  File \"/usr/local/lib/python3.10/dist-packages/scikeras/wrappers.py\", line 936, in _fit\n    self._check_model_compatibility(y)\n  File \"/usr/local/lib/python3.10/dist-packages/scikeras/wrappers.py\", line 559, in _check_model_compatibility\n    if self.n_outputs_expected_ != len(self.model_.outputs):\n  File \"/usr/local/lib/python3.10/dist-packages/keras/src/models/sequential.py\", line 292, in outputs\n    raise ValueError(\nValueError: Sequential model 'sequential_133' has no defined outputs yet.\n\n--------------------------------------------------------------------------------\n1 fits failed with the following error:\nTraceback (most recent call last):\n  File \"/usr/local/lib/python3.10/dist-packages/sklearn/model_selection/_validation.py\", line 888, in _fit_and_score\n    estimator.fit(X_train, y_train, **fit_params)\n  File \"/usr/local/lib/python3.10/dist-packages/scikeras/wrappers.py\", line 1501, in fit\n    super().fit(X=X, y=y, sample_weight=sample_weight, **kwargs)\n  File \"/usr/local/lib/python3.10/dist-packages/scikeras/wrappers.py\", line 770, in fit\n    self._fit(\n  File \"/usr/local/lib/python3.10/dist-packages/scikeras/wrappers.py\", line 936, in _fit\n    self._check_model_compatibility(y)\n  File \"/usr/local/lib/python3.10/dist-packages/scikeras/wrappers.py\", line 559, in _check_model_compatibility\n    if self.n_outputs_expected_ != len(self.model_.outputs):\n  File \"/usr/local/lib/python3.10/dist-packages/keras/src/models/sequential.py\", line 292, in outputs\n    raise ValueError(\nValueError: Sequential model 'sequential_134' has no defined outputs yet.\n\n--------------------------------------------------------------------------------\n1 fits failed with the following error:\nTraceback (most recent call last):\n  File \"/usr/local/lib/python3.10/dist-packages/sklearn/model_selection/_validation.py\", line 888, in _fit_and_score\n    estimator.fit(X_train, y_train, **fit_params)\n  File \"/usr/local/lib/python3.10/dist-packages/scikeras/wrappers.py\", line 1501, in fit\n    super().fit(X=X, y=y, sample_weight=sample_weight, **kwargs)\n  File \"/usr/local/lib/python3.10/dist-packages/scikeras/wrappers.py\", line 770, in fit\n    self._fit(\n  File \"/usr/local/lib/python3.10/dist-packages/scikeras/wrappers.py\", line 936, in _fit\n    self._check_model_compatibility(y)\n  File \"/usr/local/lib/python3.10/dist-packages/scikeras/wrappers.py\", line 559, in _check_model_compatibility\n    if self.n_outputs_expected_ != len(self.model_.outputs):\n  File \"/usr/local/lib/python3.10/dist-packages/keras/src/models/sequential.py\", line 292, in outputs\n    raise ValueError(\nValueError: Sequential model 'sequential_135' has no defined outputs yet.\n\n--------------------------------------------------------------------------------\n1 fits failed with the following error:\nTraceback (most recent call last):\n  File \"/usr/local/lib/python3.10/dist-packages/sklearn/model_selection/_validation.py\", line 888, in _fit_and_score\n    estimator.fit(X_train, y_train, **fit_params)\n  File \"/usr/local/lib/python3.10/dist-packages/scikeras/wrappers.py\", line 1501, in fit\n    super().fit(X=X, y=y, sample_weight=sample_weight, **kwargs)\n  File \"/usr/local/lib/python3.10/dist-packages/scikeras/wrappers.py\", line 770, in fit\n    self._fit(\n  File \"/usr/local/lib/python3.10/dist-packages/scikeras/wrappers.py\", line 936, in _fit\n    self._check_model_compatibility(y)\n  File \"/usr/local/lib/python3.10/dist-packages/scikeras/wrappers.py\", line 559, in _check_model_compatibility\n    if self.n_outputs_expected_ != len(self.model_.outputs):\n  File \"/usr/local/lib/python3.10/dist-packages/keras/src/models/sequential.py\", line 292, in outputs\n    raise ValueError(\nValueError: Sequential model 'sequential_136' has no defined outputs yet.\n\n--------------------------------------------------------------------------------\n1 fits failed with the following error:\nTraceback (most recent call last):\n  File \"/usr/local/lib/python3.10/dist-packages/sklearn/model_selection/_validation.py\", line 888, in _fit_and_score\n    estimator.fit(X_train, y_train, **fit_params)\n  File \"/usr/local/lib/python3.10/dist-packages/scikeras/wrappers.py\", line 1501, in fit\n    super().fit(X=X, y=y, sample_weight=sample_weight, **kwargs)\n  File \"/usr/local/lib/python3.10/dist-packages/scikeras/wrappers.py\", line 770, in fit\n    self._fit(\n  File \"/usr/local/lib/python3.10/dist-packages/scikeras/wrappers.py\", line 936, in _fit\n    self._check_model_compatibility(y)\n  File \"/usr/local/lib/python3.10/dist-packages/scikeras/wrappers.py\", line 559, in _check_model_compatibility\n    if self.n_outputs_expected_ != len(self.model_.outputs):\n  File \"/usr/local/lib/python3.10/dist-packages/keras/src/models/sequential.py\", line 292, in outputs\n    raise ValueError(\nValueError: Sequential model 'sequential_137' has no defined outputs yet.\n\n--------------------------------------------------------------------------------\n1 fits failed with the following error:\nTraceback (most recent call last):\n  File \"/usr/local/lib/python3.10/dist-packages/sklearn/model_selection/_validation.py\", line 888, in _fit_and_score\n    estimator.fit(X_train, y_train, **fit_params)\n  File \"/usr/local/lib/python3.10/dist-packages/scikeras/wrappers.py\", line 1501, in fit\n    super().fit(X=X, y=y, sample_weight=sample_weight, **kwargs)\n  File \"/usr/local/lib/python3.10/dist-packages/scikeras/wrappers.py\", line 770, in fit\n    self._fit(\n  File \"/usr/local/lib/python3.10/dist-packages/scikeras/wrappers.py\", line 936, in _fit\n    self._check_model_compatibility(y)\n  File \"/usr/local/lib/python3.10/dist-packages/scikeras/wrappers.py\", line 559, in _check_model_compatibility\n    if self.n_outputs_expected_ != len(self.model_.outputs):\n  File \"/usr/local/lib/python3.10/dist-packages/keras/src/models/sequential.py\", line 292, in outputs\n    raise ValueError(\nValueError: Sequential model 'sequential_138' has no defined outputs yet.\n\n--------------------------------------------------------------------------------\n1 fits failed with the following error:\nTraceback (most recent call last):\n  File \"/usr/local/lib/python3.10/dist-packages/sklearn/model_selection/_validation.py\", line 888, in _fit_and_score\n    estimator.fit(X_train, y_train, **fit_params)\n  File \"/usr/local/lib/python3.10/dist-packages/scikeras/wrappers.py\", line 1501, in fit\n    super().fit(X=X, y=y, sample_weight=sample_weight, **kwargs)\n  File \"/usr/local/lib/python3.10/dist-packages/scikeras/wrappers.py\", line 770, in fit\n    self._fit(\n  File \"/usr/local/lib/python3.10/dist-packages/scikeras/wrappers.py\", line 936, in _fit\n    self._check_model_compatibility(y)\n  File \"/usr/local/lib/python3.10/dist-packages/scikeras/wrappers.py\", line 559, in _check_model_compatibility\n    if self.n_outputs_expected_ != len(self.model_.outputs):\n  File \"/usr/local/lib/python3.10/dist-packages/keras/src/models/sequential.py\", line 292, in outputs\n    raise ValueError(\nValueError: Sequential model 'sequential_139' has no defined outputs yet.\n\n--------------------------------------------------------------------------------\n1 fits failed with the following error:\nTraceback (most recent call last):\n  File \"/usr/local/lib/python3.10/dist-packages/sklearn/model_selection/_validation.py\", line 888, in _fit_and_score\n    estimator.fit(X_train, y_train, **fit_params)\n  File \"/usr/local/lib/python3.10/dist-packages/scikeras/wrappers.py\", line 1501, in fit\n    super().fit(X=X, y=y, sample_weight=sample_weight, **kwargs)\n  File \"/usr/local/lib/python3.10/dist-packages/scikeras/wrappers.py\", line 770, in fit\n    self._fit(\n  File \"/usr/local/lib/python3.10/dist-packages/scikeras/wrappers.py\", line 936, in _fit\n    self._check_model_compatibility(y)\n  File \"/usr/local/lib/python3.10/dist-packages/scikeras/wrappers.py\", line 559, in _check_model_compatibility\n    if self.n_outputs_expected_ != len(self.model_.outputs):\n  File \"/usr/local/lib/python3.10/dist-packages/keras/src/models/sequential.py\", line 292, in outputs\n    raise ValueError(\nValueError: Sequential model 'sequential_140' has no defined outputs yet.\n\n--------------------------------------------------------------------------------\n1 fits failed with the following error:\nTraceback (most recent call last):\n  File \"/usr/local/lib/python3.10/dist-packages/sklearn/model_selection/_validation.py\", line 888, in _fit_and_score\n    estimator.fit(X_train, y_train, **fit_params)\n  File \"/usr/local/lib/python3.10/dist-packages/scikeras/wrappers.py\", line 1501, in fit\n    super().fit(X=X, y=y, sample_weight=sample_weight, **kwargs)\n  File \"/usr/local/lib/python3.10/dist-packages/scikeras/wrappers.py\", line 770, in fit\n    self._fit(\n  File \"/usr/local/lib/python3.10/dist-packages/scikeras/wrappers.py\", line 936, in _fit\n    self._check_model_compatibility(y)\n  File \"/usr/local/lib/python3.10/dist-packages/scikeras/wrappers.py\", line 559, in _check_model_compatibility\n    if self.n_outputs_expected_ != len(self.model_.outputs):\n  File \"/usr/local/lib/python3.10/dist-packages/keras/src/models/sequential.py\", line 292, in outputs\n    raise ValueError(\nValueError: Sequential model 'sequential_141' has no defined outputs yet.\n\n--------------------------------------------------------------------------------\n1 fits failed with the following error:\nTraceback (most recent call last):\n  File \"/usr/local/lib/python3.10/dist-packages/sklearn/model_selection/_validation.py\", line 888, in _fit_and_score\n    estimator.fit(X_train, y_train, **fit_params)\n  File \"/usr/local/lib/python3.10/dist-packages/scikeras/wrappers.py\", line 1501, in fit\n    super().fit(X=X, y=y, sample_weight=sample_weight, **kwargs)\n  File \"/usr/local/lib/python3.10/dist-packages/scikeras/wrappers.py\", line 770, in fit\n    self._fit(\n  File \"/usr/local/lib/python3.10/dist-packages/scikeras/wrappers.py\", line 936, in _fit\n    self._check_model_compatibility(y)\n  File \"/usr/local/lib/python3.10/dist-packages/scikeras/wrappers.py\", line 559, in _check_model_compatibility\n    if self.n_outputs_expected_ != len(self.model_.outputs):\n  File \"/usr/local/lib/python3.10/dist-packages/keras/src/models/sequential.py\", line 292, in outputs\n    raise ValueError(\nValueError: Sequential model 'sequential_142' has no defined outputs yet.\n\n--------------------------------------------------------------------------------\n1 fits failed with the following error:\nTraceback (most recent call last):\n  File \"/usr/local/lib/python3.10/dist-packages/sklearn/model_selection/_validation.py\", line 888, in _fit_and_score\n    estimator.fit(X_train, y_train, **fit_params)\n  File \"/usr/local/lib/python3.10/dist-packages/scikeras/wrappers.py\", line 1501, in fit\n    super().fit(X=X, y=y, sample_weight=sample_weight, **kwargs)\n  File \"/usr/local/lib/python3.10/dist-packages/scikeras/wrappers.py\", line 770, in fit\n    self._fit(\n  File \"/usr/local/lib/python3.10/dist-packages/scikeras/wrappers.py\", line 936, in _fit\n    self._check_model_compatibility(y)\n  File \"/usr/local/lib/python3.10/dist-packages/scikeras/wrappers.py\", line 559, in _check_model_compatibility\n    if self.n_outputs_expected_ != len(self.model_.outputs):\n  File \"/usr/local/lib/python3.10/dist-packages/keras/src/models/sequential.py\", line 292, in outputs\n    raise ValueError(\nValueError: Sequential model 'sequential_143' has no defined outputs yet.\n\n--------------------------------------------------------------------------------\n1 fits failed with the following error:\nTraceback (most recent call last):\n  File \"/usr/local/lib/python3.10/dist-packages/sklearn/model_selection/_validation.py\", line 888, in _fit_and_score\n    estimator.fit(X_train, y_train, **fit_params)\n  File \"/usr/local/lib/python3.10/dist-packages/scikeras/wrappers.py\", line 1501, in fit\n    super().fit(X=X, y=y, sample_weight=sample_weight, **kwargs)\n  File \"/usr/local/lib/python3.10/dist-packages/scikeras/wrappers.py\", line 770, in fit\n    self._fit(\n  File \"/usr/local/lib/python3.10/dist-packages/scikeras/wrappers.py\", line 936, in _fit\n    self._check_model_compatibility(y)\n  File \"/usr/local/lib/python3.10/dist-packages/scikeras/wrappers.py\", line 559, in _check_model_compatibility\n    if self.n_outputs_expected_ != len(self.model_.outputs):\n  File \"/usr/local/lib/python3.10/dist-packages/keras/src/models/sequential.py\", line 292, in outputs\n    raise ValueError(\nValueError: Sequential model 'sequential_144' has no defined outputs yet.\n\n--------------------------------------------------------------------------------\n1 fits failed with the following error:\nTraceback (most recent call last):\n  File \"/usr/local/lib/python3.10/dist-packages/sklearn/model_selection/_validation.py\", line 888, in _fit_and_score\n    estimator.fit(X_train, y_train, **fit_params)\n  File \"/usr/local/lib/python3.10/dist-packages/scikeras/wrappers.py\", line 1501, in fit\n    super().fit(X=X, y=y, sample_weight=sample_weight, **kwargs)\n  File \"/usr/local/lib/python3.10/dist-packages/scikeras/wrappers.py\", line 770, in fit\n    self._fit(\n  File \"/usr/local/lib/python3.10/dist-packages/scikeras/wrappers.py\", line 936, in _fit\n    self._check_model_compatibility(y)\n  File \"/usr/local/lib/python3.10/dist-packages/scikeras/wrappers.py\", line 559, in _check_model_compatibility\n    if self.n_outputs_expected_ != len(self.model_.outputs):\n  File \"/usr/local/lib/python3.10/dist-packages/keras/src/models/sequential.py\", line 292, in outputs\n    raise ValueError(\nValueError: Sequential model 'sequential_145' has no defined outputs yet.\n\n--------------------------------------------------------------------------------\n1 fits failed with the following error:\nTraceback (most recent call last):\n  File \"/usr/local/lib/python3.10/dist-packages/sklearn/model_selection/_validation.py\", line 888, in _fit_and_score\n    estimator.fit(X_train, y_train, **fit_params)\n  File \"/usr/local/lib/python3.10/dist-packages/scikeras/wrappers.py\", line 1501, in fit\n    super().fit(X=X, y=y, sample_weight=sample_weight, **kwargs)\n  File \"/usr/local/lib/python3.10/dist-packages/scikeras/wrappers.py\", line 770, in fit\n    self._fit(\n  File \"/usr/local/lib/python3.10/dist-packages/scikeras/wrappers.py\", line 936, in _fit\n    self._check_model_compatibility(y)\n  File \"/usr/local/lib/python3.10/dist-packages/scikeras/wrappers.py\", line 559, in _check_model_compatibility\n    if self.n_outputs_expected_ != len(self.model_.outputs):\n  File \"/usr/local/lib/python3.10/dist-packages/keras/src/models/sequential.py\", line 292, in outputs\n    raise ValueError(\nValueError: Sequential model 'sequential_146' has no defined outputs yet.\n",
          "traceback": [
            "\u001b[0;31m---------------------------------------------------------------------------\u001b[0m",
            "\u001b[0;31mValueError\u001b[0m                                Traceback (most recent call last)",
            "\u001b[0;32m<ipython-input-43-3440bb3762df>\u001b[0m in \u001b[0;36m<cell line: 55>\u001b[0;34m()\u001b[0m\n\u001b[1;32m     53\u001b[0m }\n\u001b[1;32m     54\u001b[0m \u001b[0mgrid\u001b[0m \u001b[0;34m=\u001b[0m \u001b[0mGridSearchCV\u001b[0m\u001b[0;34m(\u001b[0m\u001b[0mestimator\u001b[0m\u001b[0;34m=\u001b[0m\u001b[0mmodel\u001b[0m\u001b[0;34m,\u001b[0m \u001b[0mparam_grid\u001b[0m\u001b[0;34m=\u001b[0m\u001b[0mparam_grid\u001b[0m\u001b[0;34m,\u001b[0m \u001b[0mcv\u001b[0m\u001b[0;34m=\u001b[0m\u001b[0;36m3\u001b[0m\u001b[0;34m,\u001b[0m \u001b[0mverbose\u001b[0m\u001b[0;34m=\u001b[0m\u001b[0;36m1\u001b[0m\u001b[0;34m)\u001b[0m\u001b[0;34m\u001b[0m\u001b[0;34m\u001b[0m\u001b[0m\n\u001b[0;32m---> 55\u001b[0;31m \u001b[0mgrid_result\u001b[0m \u001b[0;34m=\u001b[0m \u001b[0mgrid\u001b[0m\u001b[0;34m.\u001b[0m\u001b[0mfit\u001b[0m\u001b[0;34m(\u001b[0m\u001b[0mX_train\u001b[0m\u001b[0;34m,\u001b[0m \u001b[0mY_train\u001b[0m\u001b[0;34m)\u001b[0m\u001b[0;34m\u001b[0m\u001b[0;34m\u001b[0m\u001b[0m\n\u001b[0m\u001b[1;32m     56\u001b[0m \u001b[0;34m\u001b[0m\u001b[0m\n\u001b[1;32m     57\u001b[0m \u001b[0mprint\u001b[0m\u001b[0;34m(\u001b[0m\u001b[0;34m\"Best: %f using %s\"\u001b[0m \u001b[0;34m%\u001b[0m \u001b[0;34m(\u001b[0m\u001b[0mgrid_result\u001b[0m\u001b[0;34m.\u001b[0m\u001b[0mbest_score_\u001b[0m\u001b[0;34m,\u001b[0m \u001b[0mgrid_result\u001b[0m\u001b[0;34m.\u001b[0m\u001b[0mbest_params_\u001b[0m\u001b[0;34m)\u001b[0m\u001b[0;34m)\u001b[0m\u001b[0;34m\u001b[0m\u001b[0;34m\u001b[0m\u001b[0m\n",
            "\u001b[0;32m/usr/local/lib/python3.10/dist-packages/sklearn/base.py\u001b[0m in \u001b[0;36mwrapper\u001b[0;34m(estimator, *args, **kwargs)\u001b[0m\n\u001b[1;32m   1471\u001b[0m                 )\n\u001b[1;32m   1472\u001b[0m             ):\n\u001b[0;32m-> 1473\u001b[0;31m                 \u001b[0;32mreturn\u001b[0m \u001b[0mfit_method\u001b[0m\u001b[0;34m(\u001b[0m\u001b[0mestimator\u001b[0m\u001b[0;34m,\u001b[0m \u001b[0;34m*\u001b[0m\u001b[0margs\u001b[0m\u001b[0;34m,\u001b[0m \u001b[0;34m**\u001b[0m\u001b[0mkwargs\u001b[0m\u001b[0;34m)\u001b[0m\u001b[0;34m\u001b[0m\u001b[0;34m\u001b[0m\u001b[0m\n\u001b[0m\u001b[1;32m   1474\u001b[0m \u001b[0;34m\u001b[0m\u001b[0m\n\u001b[1;32m   1475\u001b[0m         \u001b[0;32mreturn\u001b[0m \u001b[0mwrapper\u001b[0m\u001b[0;34m\u001b[0m\u001b[0;34m\u001b[0m\u001b[0m\n",
            "\u001b[0;32m/usr/local/lib/python3.10/dist-packages/sklearn/model_selection/_search.py\u001b[0m in \u001b[0;36mfit\u001b[0;34m(self, X, y, **params)\u001b[0m\n\u001b[1;32m   1017\u001b[0m                 \u001b[0;32mreturn\u001b[0m \u001b[0mresults\u001b[0m\u001b[0;34m\u001b[0m\u001b[0;34m\u001b[0m\u001b[0m\n\u001b[1;32m   1018\u001b[0m \u001b[0;34m\u001b[0m\u001b[0m\n\u001b[0;32m-> 1019\u001b[0;31m             \u001b[0mself\u001b[0m\u001b[0;34m.\u001b[0m\u001b[0m_run_search\u001b[0m\u001b[0;34m(\u001b[0m\u001b[0mevaluate_candidates\u001b[0m\u001b[0;34m)\u001b[0m\u001b[0;34m\u001b[0m\u001b[0;34m\u001b[0m\u001b[0m\n\u001b[0m\u001b[1;32m   1020\u001b[0m \u001b[0;34m\u001b[0m\u001b[0m\n\u001b[1;32m   1021\u001b[0m             \u001b[0;31m# multimetric is determined here because in the case of a callable\u001b[0m\u001b[0;34m\u001b[0m\u001b[0;34m\u001b[0m\u001b[0m\n",
            "\u001b[0;32m/usr/local/lib/python3.10/dist-packages/sklearn/model_selection/_search.py\u001b[0m in \u001b[0;36m_run_search\u001b[0;34m(self, evaluate_candidates)\u001b[0m\n\u001b[1;32m   1571\u001b[0m     \u001b[0;32mdef\u001b[0m \u001b[0m_run_search\u001b[0m\u001b[0;34m(\u001b[0m\u001b[0mself\u001b[0m\u001b[0;34m,\u001b[0m \u001b[0mevaluate_candidates\u001b[0m\u001b[0;34m)\u001b[0m\u001b[0;34m:\u001b[0m\u001b[0;34m\u001b[0m\u001b[0;34m\u001b[0m\u001b[0m\n\u001b[1;32m   1572\u001b[0m         \u001b[0;34m\"\"\"Search all candidates in param_grid\"\"\"\u001b[0m\u001b[0;34m\u001b[0m\u001b[0;34m\u001b[0m\u001b[0m\n\u001b[0;32m-> 1573\u001b[0;31m         \u001b[0mevaluate_candidates\u001b[0m\u001b[0;34m(\u001b[0m\u001b[0mParameterGrid\u001b[0m\u001b[0;34m(\u001b[0m\u001b[0mself\u001b[0m\u001b[0;34m.\u001b[0m\u001b[0mparam_grid\u001b[0m\u001b[0;34m)\u001b[0m\u001b[0;34m)\u001b[0m\u001b[0;34m\u001b[0m\u001b[0;34m\u001b[0m\u001b[0m\n\u001b[0m\u001b[1;32m   1574\u001b[0m \u001b[0;34m\u001b[0m\u001b[0m\n\u001b[1;32m   1575\u001b[0m \u001b[0;34m\u001b[0m\u001b[0m\n",
            "\u001b[0;32m/usr/local/lib/python3.10/dist-packages/sklearn/model_selection/_search.py\u001b[0m in \u001b[0;36mevaluate_candidates\u001b[0;34m(candidate_params, cv, more_results)\u001b[0m\n\u001b[1;32m    994\u001b[0m                     )\n\u001b[1;32m    995\u001b[0m \u001b[0;34m\u001b[0m\u001b[0m\n\u001b[0;32m--> 996\u001b[0;31m                 \u001b[0m_warn_or_raise_about_fit_failures\u001b[0m\u001b[0;34m(\u001b[0m\u001b[0mout\u001b[0m\u001b[0;34m,\u001b[0m \u001b[0mself\u001b[0m\u001b[0;34m.\u001b[0m\u001b[0merror_score\u001b[0m\u001b[0;34m)\u001b[0m\u001b[0;34m\u001b[0m\u001b[0;34m\u001b[0m\u001b[0m\n\u001b[0m\u001b[1;32m    997\u001b[0m \u001b[0;34m\u001b[0m\u001b[0m\n\u001b[1;32m    998\u001b[0m                 \u001b[0;31m# For callable self.scoring, the return type is only know after\u001b[0m\u001b[0;34m\u001b[0m\u001b[0;34m\u001b[0m\u001b[0m\n",
            "\u001b[0;32m/usr/local/lib/python3.10/dist-packages/sklearn/model_selection/_validation.py\u001b[0m in \u001b[0;36m_warn_or_raise_about_fit_failures\u001b[0;34m(results, error_score)\u001b[0m\n\u001b[1;32m    527\u001b[0m                 \u001b[0;34mf\"Below are more details about the failures:\\n{fit_errors_summary}\"\u001b[0m\u001b[0;34m\u001b[0m\u001b[0;34m\u001b[0m\u001b[0m\n\u001b[1;32m    528\u001b[0m             )\n\u001b[0;32m--> 529\u001b[0;31m             \u001b[0;32mraise\u001b[0m \u001b[0mValueError\u001b[0m\u001b[0;34m(\u001b[0m\u001b[0mall_fits_failed_message\u001b[0m\u001b[0;34m)\u001b[0m\u001b[0;34m\u001b[0m\u001b[0;34m\u001b[0m\u001b[0m\n\u001b[0m\u001b[1;32m    530\u001b[0m \u001b[0;34m\u001b[0m\u001b[0m\n\u001b[1;32m    531\u001b[0m         \u001b[0;32melse\u001b[0m\u001b[0;34m:\u001b[0m\u001b[0;34m\u001b[0m\u001b[0;34m\u001b[0m\u001b[0m\n",
            "\u001b[0;31mValueError\u001b[0m: \nAll the 27 fits failed.\nIt is very likely that your model is misconfigured.\nYou can try to debug the error by setting error_score='raise'.\n\nBelow are more details about the failures:\n--------------------------------------------------------------------------------\n1 fits failed with the following error:\nTraceback (most recent call last):\n  File \"/usr/local/lib/python3.10/dist-packages/sklearn/model_selection/_validation.py\", line 888, in _fit_and_score\n    estimator.fit(X_train, y_train, **fit_params)\n  File \"/usr/local/lib/python3.10/dist-packages/scikeras/wrappers.py\", line 1501, in fit\n    super().fit(X=X, y=y, sample_weight=sample_weight, **kwargs)\n  File \"/usr/local/lib/python3.10/dist-packages/scikeras/wrappers.py\", line 770, in fit\n    self._fit(\n  File \"/usr/local/lib/python3.10/dist-packages/scikeras/wrappers.py\", line 936, in _fit\n    self._check_model_compatibility(y)\n  File \"/usr/local/lib/python3.10/dist-packages/scikeras/wrappers.py\", line 559, in _check_model_compatibility\n    if self.n_outputs_expected_ != len(self.model_.outputs):\n  File \"/usr/local/lib/python3.10/dist-packages/keras/src/models/sequential.py\", line 292, in outputs\n    raise ValueError(\nValueError: Sequential model 'sequential_120' has no defined outputs yet.\n\n--------------------------------------------------------------------------------\n1 fits failed with the following error:\nTraceback (most recent call last):\n  File \"/usr/local/lib/python3.10/dist-packages/sklearn/model_selection/_validation.py\", line 888, in _fit_and_score\n    estimator.fit(X_train, y_train, **fit_params)\n  File \"/usr/local/lib/python3.10/dist-packages/scikeras/wrappers.py\", line 1501, in fit\n    super().fit(X=X, y=y, sample_weight=sample_weight, **kwargs)\n  File \"/usr/local/lib/python3.10/dist-packages/scikeras/wrappers.py\", line 770, in fit\n    self._fit(\n  File \"/usr/local/lib/python3.10/dist-packages/scikeras/wrappers.py\", line 936, in _fit\n    self._check_model_compatibility(y)\n  File \"/usr/local/lib/python3.10/dist-packages/scikeras/wrappers.py\", line 559, in _check_model_compatibility\n    if self.n_outputs_expected_ != len(self.model_.outputs):\n  File \"/usr/local/lib/python3.10/dist-packages/keras/src/models/sequential.py\", line 292, in outputs\n    raise ValueError(\nValueError: Sequential model 'sequential_121' has no defined outputs yet.\n\n--------------------------------------------------------------------------------\n1 fits failed with the following error:\nTraceback (most recent call last):\n  File \"/usr/local/lib/python3.10/dist-packages/sklearn/model_selection/_validation.py\", line 888, in _fit_and_score\n    estimator.fit(X_train, y_train, **fit_params)\n  File \"/usr/local/lib/python3.10/dist-packages/scikeras/wrappers.py\", line 1501, in fit\n    super().fit(X=X, y=y, sample_weight=sample_weight, **kwargs)\n  File \"/usr/local/lib/python3.10/dist-packages/scikeras/wrappers.py\", line 770, in fit\n    self._fit(\n  File \"/usr/local/lib/python3.10/dist-packages/scikeras/wrappers.py\", line 936, in _fit\n    self._check_model_compatibility(y)\n  File \"/usr/local/lib/python3.10/dist-packages/scikeras/wrappers.py\", line 559, in _check_model_compatibility\n    if self.n_outputs_expected_ != len(self.model_.outputs):\n  File \"/usr/local/lib/python3.10/dist-packages/keras/src/models/sequential.py\", line 292, in outputs\n    raise ValueError(\nValueError: Sequential model 'sequential_122' has no defined outputs yet.\n\n--------------------------------------------------------------------------------\n1 fits failed with the following error:\nTraceback (most recent call last):\n  File \"/usr/local/lib/python3.10/dist-packages/sklearn/model_selection/_validation.py\", line 888, in _fit_and_score\n    estimator.fit(X_train, y_train, **fit_params)\n  File \"/usr/local/lib/python3.10/dist-packages/scikeras/wrappers.py\", line 1501, in fit\n    super().fit(X=X, y=y, sample_weight=sample_weight, **kwargs)\n  File \"/usr/local/lib/python3.10/dist-packages/scikeras/wrappers.py\", line 770, in fit\n    self._fit(\n  File \"/usr/local/lib/python3.10/dist-packages/scikeras/wrappers.py\", line 936, in _fit\n    self._check_model_compatibility(y)\n  File \"/usr/local/lib/python3.10/dist-packages/scikeras/wrappers.py\", line 559, in _check_model_compatibility\n    if self.n_outputs_expected_ != len(self.model_.outputs):\n  File \"/usr/local/lib/python3.10/dist-packages/keras/src/models/sequential.py\", line 292, in outputs\n    raise ValueError(\nValueError: Sequential model 'sequential_123' has no defined outputs yet.\n\n--------------------------------------------------------------------------------\n1 fits failed with the following error:\nTraceback (most recent call last):\n  File \"/usr/local/lib/python3.10/dist-packages/sklearn/model_selection/_validation.py\", line 888, in _fit_and_score\n    estimator.fit(X_train, y_train, **fit_params)\n  File \"/usr/local/lib/python3.10/dist-packages/scikeras/wrappers.py\", line 1501, in fit\n    super().fit(X=X, y=y, sample_weight=sample_weight, **kwargs)\n  File \"/usr/local/lib/python3.10/dist-packages/scikeras/wrappers.py\", line 770, in fit\n    self._fit(\n  File \"/usr/local/lib/python3.10/dist-packages/scikeras/wrappers.py\", line 936, in _fit\n    self._check_model_compatibility(y)\n  File \"/usr/local/lib/python3.10/dist-packages/scikeras/wrappers.py\", line 559, in _check_model_compatibility\n    if self.n_outputs_expected_ != len(self.model_.outputs):\n  File \"/usr/local/lib/python3.10/dist-packages/keras/src/models/sequential.py\", line 292, in outputs\n    raise ValueError(\nValueError: Sequential model 'sequential_124' has no defined outputs yet.\n\n--------------------------------------------------------------------------------\n1 fits failed with the following error:\nTraceback (most recent call last):\n  File \"/usr/local/lib/python3.10/dist-packages/sklearn/model_selection/_validation.py\", line 888, in _fit_and_score\n    estimator.fit(X_train, y_train, **fit_params)\n  File \"/usr/local/lib/python3.10/dist-packages/scikeras/wrappers.py\", line 1501, in fit\n    super().fit(X=X, y=y, sample_weight=sample_weight, **kwargs)\n  File \"/usr/local/lib/python3.10/dist-packages/scikeras/wrappers.py\", line 770, in fit\n    self._fit(\n  File \"/usr/local/lib/python3.10/dist-packages/scikeras/wrappers.py\", line 936, in _fit\n    self._check_model_compatibility(y)\n  File \"/usr/local/lib/python3.10/dist-packages/scikeras/wrappers.py\", line 559, in _check_model_compatibility\n    if self.n_outputs_expected_ != len(self.model_.outputs):\n  File \"/usr/local/lib/python3.10/dist-packages/keras/src/models/sequential.py\", line 292, in outputs\n    raise ValueError(\nValueError: Sequential model 'sequential_125' has no defined outputs yet.\n\n--------------------------------------------------------------------------------\n1 fits failed with the following error:\nTraceback (most recent call last):\n  File \"/usr/local/lib/python3.10/dist-packages/sklearn/model_selection/_validation.py\", line 888, in _fit_and_score\n    estimator.fit(X_train, y_train, **fit_params)\n  File \"/usr/local/lib/python3.10/dist-packages/scikeras/wrappers.py\", line 1501, in fit\n    super().fit(X=X, y=y, sample_weight=sample_weight, **kwargs)\n  File \"/usr/local/lib/python3.10/dist-packages/scikeras/wrappers.py\", line 770, in fit\n    self._fit(\n  File \"/usr/local/lib/python3.10/dist-packages/scikeras/wrappers.py\", line 936, in _fit\n    self._check_model_compatibility(y)\n  File \"/usr/local/lib/python3.10/dist-packages/scikeras/wrappers.py\", line 559, in _check_model_compatibility\n    if self.n_outputs_expected_ != len(self.model_.outputs):\n  File \"/usr/local/lib/python3.10/dist-packages/keras/src/models/sequential.py\", line 292, in outputs\n    raise ValueError(\nValueError: Sequential model 'sequential_126' has no defined outputs yet.\n\n--------------------------------------------------------------------------------\n1 fits failed with the following error:\nTraceback (most recent call last):\n  File \"/usr/local/lib/python3.10/dist-packages/sklearn/model_selection/_validation.py\", line 888, in _fit_and_score\n    estimator.fit(X_train, y_train, **fit_params)\n  File \"/usr/local/lib/python3.10/dist-packages/scikeras/wrappers.py\", line 1501, in fit\n    super().fit(X=X, y=y, sample_weight=sample_weight, **kwargs)\n  File \"/usr/local/lib/python3.10/dist-packages/scikeras/wrappers.py\", line 770, in fit\n    self._fit(\n  File \"/usr/local/lib/python3.10/dist-packages/scikeras/wrappers.py\", line 936, in _fit\n    self._check_model_compatibility(y)\n  File \"/usr/local/lib/python3.10/dist-packages/scikeras/wrappers.py\", line 559, in _check_model_compatibility\n    if self.n_outputs_expected_ != len(self.model_.outputs):\n  File \"/usr/local/lib/python3.10/dist-packages/keras/src/models/sequential.py\", line 292, in outputs\n    raise ValueError(\nValueError: Sequential model 'sequential_127' has no defined outputs yet.\n\n--------------------------------------------------------------------------------\n1 fits failed with the following error:\nTraceback (most recent call last):\n  File \"/usr/local/lib/python3.10/dist-packages/sklearn/model_selection/_validation.py\", line 888, in _fit_and_score\n    estimator.fit(X_train, y_train, **fit_params)\n  File \"/usr/local/lib/python3.10/dist-packages/scikeras/wrappers.py\", line 1501, in fit\n    super().fit(X=X, y=y, sample_weight=sample_weight, **kwargs)\n  File \"/usr/local/lib/python3.10/dist-packages/scikeras/wrappers.py\", line 770, in fit\n    self._fit(\n  File \"/usr/local/lib/python3.10/dist-packages/scikeras/wrappers.py\", line 936, in _fit\n    self._check_model_compatibility(y)\n  File \"/usr/local/lib/python3.10/dist-packages/scikeras/wrappers.py\", line 559, in _check_model_compatibility\n    if self.n_outputs_expected_ != len(self.model_.outputs):\n  File \"/usr/local/lib/python3.10/dist-packages/keras/src/models/sequential.py\", line 292, in outputs\n    raise ValueError(\nValueError: Sequential model 'sequential_128' has no defined outputs yet.\n\n--------------------------------------------------------------------------------\n1 fits failed with the following error:\nTraceback (most recent call last):\n  File \"/usr/local/lib/python3.10/dist-packages/sklearn/model_selection/_validation.py\", line 888, in _fit_and_score\n    estimator.fit(X_train, y_train, **fit_params)\n  File \"/usr/local/lib/python3.10/dist-packages/scikeras/wrappers.py\", line 1501, in fit\n    super().fit(X=X, y=y, sample_weight=sample_weight, **kwargs)\n  File \"/usr/local/lib/python3.10/dist-packages/scikeras/wrappers.py\", line 770, in fit\n    self._fit(\n  File \"/usr/local/lib/python3.10/dist-packages/scikeras/wrappers.py\", line 936, in _fit\n    self._check_model_compatibility(y)\n  File \"/usr/local/lib/python3.10/dist-packages/scikeras/wrappers.py\", line 559, in _check_model_compatibility\n    if self.n_outputs_expected_ != len(self.model_.outputs):\n  File \"/usr/local/lib/python3.10/dist-packages/keras/src/models/sequential.py\", line 292, in outputs\n    raise ValueError(\nValueError: Sequential model 'sequential_129' has no defined outputs yet.\n\n--------------------------------------------------------------------------------\n1 fits failed with the following error:\nTraceback (most recent call last):\n  File \"/usr/local/lib/python3.10/dist-packages/sklearn/model_selection/_validation.py\", line 888, in _fit_and_score\n    estimator.fit(X_train, y_train, **fit_params)\n  File \"/usr/local/lib/python3.10/dist-packages/scikeras/wrappers.py\", line 1501, in fit\n    super().fit(X=X, y=y, sample_weight=sample_weight, **kwargs)\n  File \"/usr/local/lib/python3.10/dist-packages/scikeras/wrappers.py\", line 770, in fit\n    self._fit(\n  File \"/usr/local/lib/python3.10/dist-packages/scikeras/wrappers.py\", line 936, in _fit\n    self._check_model_compatibility(y)\n  File \"/usr/local/lib/python3.10/dist-packages/scikeras/wrappers.py\", line 559, in _check_model_compatibility\n    if self.n_outputs_expected_ != len(self.model_.outputs):\n  File \"/usr/local/lib/python3.10/dist-packages/keras/src/models/sequential.py\", line 292, in outputs\n    raise ValueError(\nValueError: Sequential model 'sequential_130' has no defined outputs yet.\n\n--------------------------------------------------------------------------------\n1 fits failed with the following error:\nTraceback (most recent call last):\n  File \"/usr/local/lib/python3.10/dist-packages/sklearn/model_selection/_validation.py\", line 888, in _fit_and_score\n    estimator.fit(X_train, y_train, **fit_params)\n  File \"/usr/local/lib/python3.10/dist-packages/scikeras/wrappers.py\", line 1501, in fit\n    super().fit(X=X, y=y, sample_weight=sample_weight, **kwargs)\n  File \"/usr/local/lib/python3.10/dist-packages/scikeras/wrappers.py\", line 770, in fit\n    self._fit(\n  File \"/usr/local/lib/python3.10/dist-packages/scikeras/wrappers.py\", line 936, in _fit\n    self._check_model_compatibility(y)\n  File \"/usr/local/lib/python3.10/dist-packages/scikeras/wrappers.py\", line 559, in _check_model_compatibility\n    if self.n_outputs_expected_ != len(self.model_.outputs):\n  File \"/usr/local/lib/python3.10/dist-packages/keras/src/models/sequential.py\", line 292, in outputs\n    raise ValueError(\nValueError: Sequential model 'sequential_131' has no defined outputs yet.\n\n--------------------------------------------------------------------------------\n1 fits failed with the following error:\nTraceback (most recent call last):\n  File \"/usr/local/lib/python3.10/dist-packages/sklearn/model_selection/_validation.py\", line 888, in _fit_and_score\n    estimator.fit(X_train, y_train, **fit_params)\n  File \"/usr/local/lib/python3.10/dist-packages/scikeras/wrappers.py\", line 1501, in fit\n    super().fit(X=X, y=y, sample_weight=sample_weight, **kwargs)\n  File \"/usr/local/lib/python3.10/dist-packages/scikeras/wrappers.py\", line 770, in fit\n    self._fit(\n  File \"/usr/local/lib/python3.10/dist-packages/scikeras/wrappers.py\", line 936, in _fit\n    self._check_model_compatibility(y)\n  File \"/usr/local/lib/python3.10/dist-packages/scikeras/wrappers.py\", line 559, in _check_model_compatibility\n    if self.n_outputs_expected_ != len(self.model_.outputs):\n  File \"/usr/local/lib/python3.10/dist-packages/keras/src/models/sequential.py\", line 292, in outputs\n    raise ValueError(\nValueError: Sequential model 'sequential_132' has no defined outputs yet.\n\n--------------------------------------------------------------------------------\n1 fits failed with the following error:\nTraceback (most recent call last):\n  File \"/usr/local/lib/python3.10/dist-packages/sklearn/model_selection/_validation.py\", line 888, in _fit_and_score\n    estimator.fit(X_train, y_train, **fit_params)\n  File \"/usr/local/lib/python3.10/dist-packages/scikeras/wrappers.py\", line 1501, in fit\n    super().fit(X=X, y=y, sample_weight=sample_weight, **kwargs)\n  File \"/usr/local/lib/python3.10/dist-packages/scikeras/wrappers.py\", line 770, in fit\n    self._fit(\n  File \"/usr/local/lib/python3.10/dist-packages/scikeras/wrappers.py\", line 936, in _fit\n    self._check_model_compatibility(y)\n  File \"/usr/local/lib/python3.10/dist-packages/scikeras/wrappers.py\", line 559, in _check_model_compatibility\n    if self.n_outputs_expected_ != len(self.model_.outputs):\n  File \"/usr/local/lib/python3.10/dist-packages/keras/src/models/sequential.py\", line 292, in outputs\n    raise ValueError(\nValueError: Sequential model 'sequential_133' has no defined outputs yet.\n\n--------------------------------------------------------------------------------\n1 fits failed with the following error:\nTraceback (most recent call last):\n  File \"/usr/local/lib/python3.10/dist-packages/sklearn/model_selection/_validation.py\", line 888, in _fit_and_score\n    estimator.fit(X_train, y_train, **fit_params)\n  File \"/usr/local/lib/python3.10/dist-packages/scikeras/wrappers.py\", line 1501, in fit\n    super().fit(X=X, y=y, sample_weight=sample_weight, **kwargs)\n  File \"/usr/local/lib/python3.10/dist-packages/scikeras/wrappers.py\", line 770, in fit\n    self._fit(\n  File \"/usr/local/lib/python3.10/dist-packages/scikeras/wrappers.py\", line 936, in _fit\n    self._check_model_compatibility(y)\n  File \"/usr/local/lib/python3.10/dist-packages/scikeras/wrappers.py\", line 559, in _check_model_compatibility\n    if self.n_outputs_expected_ != len(self.model_.outputs):\n  File \"/usr/local/lib/python3.10/dist-packages/keras/src/models/sequential.py\", line 292, in outputs\n    raise ValueError(\nValueError: Sequential model 'sequential_134' has no defined outputs yet.\n\n--------------------------------------------------------------------------------\n1 fits failed with the following error:\nTraceback (most recent call last):\n  File \"/usr/local/lib/python3.10/dist-packages/sklearn/model_selection/_validation.py\", line 888, in _fit_and_score\n    estimator.fit(X_train, y_train, **fit_params)\n  File \"/usr/local/lib/python3.10/dist-packages/scikeras/wrappers.py\", line 1501, in fit\n    super().fit(X=X, y=y, sample_weight=sample_weight, **kwargs)\n  File \"/usr/local/lib/python3.10/dist-packages/scikeras/wrappers.py\", line 770, in fit\n    self._fit(\n  File \"/usr/local/lib/python3.10/dist-packages/scikeras/wrappers.py\", line 936, in _fit\n    self._check_model_compatibility(y)\n  File \"/usr/local/lib/python3.10/dist-packages/scikeras/wrappers.py\", line 559, in _check_model_compatibility\n    if self.n_outputs_expected_ != len(self.model_.outputs):\n  File \"/usr/local/lib/python3.10/dist-packages/keras/src/models/sequential.py\", line 292, in outputs\n    raise ValueError(\nValueError: Sequential model 'sequential_135' has no defined outputs yet.\n\n--------------------------------------------------------------------------------\n1 fits failed with the following error:\nTraceback (most recent call last):\n  File \"/usr/local/lib/python3.10/dist-packages/sklearn/model_selection/_validation.py\", line 888, in _fit_and_score\n    estimator.fit(X_train, y_train, **fit_params)\n  File \"/usr/local/lib/python3.10/dist-packages/scikeras/wrappers.py\", line 1501, in fit\n    super().fit(X=X, y=y, sample_weight=sample_weight, **kwargs)\n  File \"/usr/local/lib/python3.10/dist-packages/scikeras/wrappers.py\", line 770, in fit\n    self._fit(\n  File \"/usr/local/lib/python3.10/dist-packages/scikeras/wrappers.py\", line 936, in _fit\n    self._check_model_compatibility(y)\n  File \"/usr/local/lib/python3.10/dist-packages/scikeras/wrappers.py\", line 559, in _check_model_compatibility\n    if self.n_outputs_expected_ != len(self.model_.outputs):\n  File \"/usr/local/lib/python3.10/dist-packages/keras/src/models/sequential.py\", line 292, in outputs\n    raise ValueError(\nValueError: Sequential model 'sequential_136' has no defined outputs yet.\n\n--------------------------------------------------------------------------------\n1 fits failed with the following error:\nTraceback (most recent call last):\n  File \"/usr/local/lib/python3.10/dist-packages/sklearn/model_selection/_validation.py\", line 888, in _fit_and_score\n    estimator.fit(X_train, y_train, **fit_params)\n  File \"/usr/local/lib/python3.10/dist-packages/scikeras/wrappers.py\", line 1501, in fit\n    super().fit(X=X, y=y, sample_weight=sample_weight, **kwargs)\n  File \"/usr/local/lib/python3.10/dist-packages/scikeras/wrappers.py\", line 770, in fit\n    self._fit(\n  File \"/usr/local/lib/python3.10/dist-packages/scikeras/wrappers.py\", line 936, in _fit\n    self._check_model_compatibility(y)\n  File \"/usr/local/lib/python3.10/dist-packages/scikeras/wrappers.py\", line 559, in _check_model_compatibility\n    if self.n_outputs_expected_ != len(self.model_.outputs):\n  File \"/usr/local/lib/python3.10/dist-packages/keras/src/models/sequential.py\", line 292, in outputs\n    raise ValueError(\nValueError: Sequential model 'sequential_137' has no defined outputs yet.\n\n--------------------------------------------------------------------------------\n1 fits failed with the following error:\nTraceback (most recent call last):\n  File \"/usr/local/lib/python3.10/dist-packages/sklearn/model_selection/_validation.py\", line 888, in _fit_and_score\n    estimator.fit(X_train, y_train, **fit_params)\n  File \"/usr/local/lib/python3.10/dist-packages/scikeras/wrappers.py\", line 1501, in fit\n    super().fit(X=X, y=y, sample_weight=sample_weight, **kwargs)\n  File \"/usr/local/lib/python3.10/dist-packages/scikeras/wrappers.py\", line 770, in fit\n    self._fit(\n  File \"/usr/local/lib/python3.10/dist-packages/scikeras/wrappers.py\", line 936, in _fit\n    self._check_model_compatibility(y)\n  File \"/usr/local/lib/python3.10/dist-packages/scikeras/wrappers.py\", line 559, in _check_model_compatibility\n    if self.n_outputs_expected_ != len(self.model_.outputs):\n  File \"/usr/local/lib/python3.10/dist-packages/keras/src/models/sequential.py\", line 292, in outputs\n    raise ValueError(\nValueError: Sequential model 'sequential_138' has no defined outputs yet.\n\n--------------------------------------------------------------------------------\n1 fits failed with the following error:\nTraceback (most recent call last):\n  File \"/usr/local/lib/python3.10/dist-packages/sklearn/model_selection/_validation.py\", line 888, in _fit_and_score\n    estimator.fit(X_train, y_train, **fit_params)\n  File \"/usr/local/lib/python3.10/dist-packages/scikeras/wrappers.py\", line 1501, in fit\n    super().fit(X=X, y=y, sample_weight=sample_weight, **kwargs)\n  File \"/usr/local/lib/python3.10/dist-packages/scikeras/wrappers.py\", line 770, in fit\n    self._fit(\n  File \"/usr/local/lib/python3.10/dist-packages/scikeras/wrappers.py\", line 936, in _fit\n    self._check_model_compatibility(y)\n  File \"/usr/local/lib/python3.10/dist-packages/scikeras/wrappers.py\", line 559, in _check_model_compatibility\n    if self.n_outputs_expected_ != len(self.model_.outputs):\n  File \"/usr/local/lib/python3.10/dist-packages/keras/src/models/sequential.py\", line 292, in outputs\n    raise ValueError(\nValueError: Sequential model 'sequential_139' has no defined outputs yet.\n\n--------------------------------------------------------------------------------\n1 fits failed with the following error:\nTraceback (most recent call last):\n  File \"/usr/local/lib/python3.10/dist-packages/sklearn/model_selection/_validation.py\", line 888, in _fit_and_score\n    estimator.fit(X_train, y_train, **fit_params)\n  File \"/usr/local/lib/python3.10/dist-packages/scikeras/wrappers.py\", line 1501, in fit\n    super().fit(X=X, y=y, sample_weight=sample_weight, **kwargs)\n  File \"/usr/local/lib/python3.10/dist-packages/scikeras/wrappers.py\", line 770, in fit\n    self._fit(\n  File \"/usr/local/lib/python3.10/dist-packages/scikeras/wrappers.py\", line 936, in _fit\n    self._check_model_compatibility(y)\n  File \"/usr/local/lib/python3.10/dist-packages/scikeras/wrappers.py\", line 559, in _check_model_compatibility\n    if self.n_outputs_expected_ != len(self.model_.outputs):\n  File \"/usr/local/lib/python3.10/dist-packages/keras/src/models/sequential.py\", line 292, in outputs\n    raise ValueError(\nValueError: Sequential model 'sequential_140' has no defined outputs yet.\n\n--------------------------------------------------------------------------------\n1 fits failed with the following error:\nTraceback (most recent call last):\n  File \"/usr/local/lib/python3.10/dist-packages/sklearn/model_selection/_validation.py\", line 888, in _fit_and_score\n    estimator.fit(X_train, y_train, **fit_params)\n  File \"/usr/local/lib/python3.10/dist-packages/scikeras/wrappers.py\", line 1501, in fit\n    super().fit(X=X, y=y, sample_weight=sample_weight, **kwargs)\n  File \"/usr/local/lib/python3.10/dist-packages/scikeras/wrappers.py\", line 770, in fit\n    self._fit(\n  File \"/usr/local/lib/python3.10/dist-packages/scikeras/wrappers.py\", line 936, in _fit\n    self._check_model_compatibility(y)\n  File \"/usr/local/lib/python3.10/dist-packages/scikeras/wrappers.py\", line 559, in _check_model_compatibility\n    if self.n_outputs_expected_ != len(self.model_.outputs):\n  File \"/usr/local/lib/python3.10/dist-packages/keras/src/models/sequential.py\", line 292, in outputs\n    raise ValueError(\nValueError: Sequential model 'sequential_141' has no defined outputs yet.\n\n--------------------------------------------------------------------------------\n1 fits failed with the following error:\nTraceback (most recent call last):\n  File \"/usr/local/lib/python3.10/dist-packages/sklearn/model_selection/_validation.py\", line 888, in _fit_and_score\n    estimator.fit(X_train, y_train, **fit_params)\n  File \"/usr/local/lib/python3.10/dist-packages/scikeras/wrappers.py\", line 1501, in fit\n    super().fit(X=X, y=y, sample_weight=sample_weight, **kwargs)\n  File \"/usr/local/lib/python3.10/dist-packages/scikeras/wrappers.py\", line 770, in fit\n    self._fit(\n  File \"/usr/local/lib/python3.10/dist-packages/scikeras/wrappers.py\", line 936, in _fit\n    self._check_model_compatibility(y)\n  File \"/usr/local/lib/python3.10/dist-packages/scikeras/wrappers.py\", line 559, in _check_model_compatibility\n    if self.n_outputs_expected_ != len(self.model_.outputs):\n  File \"/usr/local/lib/python3.10/dist-packages/keras/src/models/sequential.py\", line 292, in outputs\n    raise ValueError(\nValueError: Sequential model 'sequential_142' has no defined outputs yet.\n\n--------------------------------------------------------------------------------\n1 fits failed with the following error:\nTraceback (most recent call last):\n  File \"/usr/local/lib/python3.10/dist-packages/sklearn/model_selection/_validation.py\", line 888, in _fit_and_score\n    estimator.fit(X_train, y_train, **fit_params)\n  File \"/usr/local/lib/python3.10/dist-packages/scikeras/wrappers.py\", line 1501, in fit\n    super().fit(X=X, y=y, sample_weight=sample_weight, **kwargs)\n  File \"/usr/local/lib/python3.10/dist-packages/scikeras/wrappers.py\", line 770, in fit\n    self._fit(\n  File \"/usr/local/lib/python3.10/dist-packages/scikeras/wrappers.py\", line 936, in _fit\n    self._check_model_compatibility(y)\n  File \"/usr/local/lib/python3.10/dist-packages/scikeras/wrappers.py\", line 559, in _check_model_compatibility\n    if self.n_outputs_expected_ != len(self.model_.outputs):\n  File \"/usr/local/lib/python3.10/dist-packages/keras/src/models/sequential.py\", line 292, in outputs\n    raise ValueError(\nValueError: Sequential model 'sequential_143' has no defined outputs yet.\n\n--------------------------------------------------------------------------------\n1 fits failed with the following error:\nTraceback (most recent call last):\n  File \"/usr/local/lib/python3.10/dist-packages/sklearn/model_selection/_validation.py\", line 888, in _fit_and_score\n    estimator.fit(X_train, y_train, **fit_params)\n  File \"/usr/local/lib/python3.10/dist-packages/scikeras/wrappers.py\", line 1501, in fit\n    super().fit(X=X, y=y, sample_weight=sample_weight, **kwargs)\n  File \"/usr/local/lib/python3.10/dist-packages/scikeras/wrappers.py\", line 770, in fit\n    self._fit(\n  File \"/usr/local/lib/python3.10/dist-packages/scikeras/wrappers.py\", line 936, in _fit\n    self._check_model_compatibility(y)\n  File \"/usr/local/lib/python3.10/dist-packages/scikeras/wrappers.py\", line 559, in _check_model_compatibility\n    if self.n_outputs_expected_ != len(self.model_.outputs):\n  File \"/usr/local/lib/python3.10/dist-packages/keras/src/models/sequential.py\", line 292, in outputs\n    raise ValueError(\nValueError: Sequential model 'sequential_144' has no defined outputs yet.\n\n--------------------------------------------------------------------------------\n1 fits failed with the following error:\nTraceback (most recent call last):\n  File \"/usr/local/lib/python3.10/dist-packages/sklearn/model_selection/_validation.py\", line 888, in _fit_and_score\n    estimator.fit(X_train, y_train, **fit_params)\n  File \"/usr/local/lib/python3.10/dist-packages/scikeras/wrappers.py\", line 1501, in fit\n    super().fit(X=X, y=y, sample_weight=sample_weight, **kwargs)\n  File \"/usr/local/lib/python3.10/dist-packages/scikeras/wrappers.py\", line 770, in fit\n    self._fit(\n  File \"/usr/local/lib/python3.10/dist-packages/scikeras/wrappers.py\", line 936, in _fit\n    self._check_model_compatibility(y)\n  File \"/usr/local/lib/python3.10/dist-packages/scikeras/wrappers.py\", line 559, in _check_model_compatibility\n    if self.n_outputs_expected_ != len(self.model_.outputs):\n  File \"/usr/local/lib/python3.10/dist-packages/keras/src/models/sequential.py\", line 292, in outputs\n    raise ValueError(\nValueError: Sequential model 'sequential_145' has no defined outputs yet.\n\n--------------------------------------------------------------------------------\n1 fits failed with the following error:\nTraceback (most recent call last):\n  File \"/usr/local/lib/python3.10/dist-packages/sklearn/model_selection/_validation.py\", line 888, in _fit_and_score\n    estimator.fit(X_train, y_train, **fit_params)\n  File \"/usr/local/lib/python3.10/dist-packages/scikeras/wrappers.py\", line 1501, in fit\n    super().fit(X=X, y=y, sample_weight=sample_weight, **kwargs)\n  File \"/usr/local/lib/python3.10/dist-packages/scikeras/wrappers.py\", line 770, in fit\n    self._fit(\n  File \"/usr/local/lib/python3.10/dist-packages/scikeras/wrappers.py\", line 936, in _fit\n    self._check_model_compatibility(y)\n  File \"/usr/local/lib/python3.10/dist-packages/scikeras/wrappers.py\", line 559, in _check_model_compatibility\n    if self.n_outputs_expected_ != len(self.model_.outputs):\n  File \"/usr/local/lib/python3.10/dist-packages/keras/src/models/sequential.py\", line 292, in outputs\n    raise ValueError(\nValueError: Sequential model 'sequential_146' has no defined outputs yet.\n"
          ]
        }
      ],
      "source": [
        "import pandas as pd # data processing, CSV file I/O (e.g. pd.read_csv)\n",
        "from tensorflow.keras.preprocessing.text import Tokenizer\n",
        "from tensorflow.keras.preprocessing.sequence import pad_sequences\n",
        "from tensorflow.keras.models import Sequential\n",
        "from tensorflow.keras.layers import Dense, Embedding, LSTM, SpatialDropout1D\n",
        "from matplotlib import pyplot\n",
        "from sklearn.model_selection import train_test_split\n",
        "from tensorflow.keras.utils import to_categorical\n",
        "from scikeras.wrappers import KerasClassifier\n",
        "from sklearn.model_selection import GridSearchCV\n",
        "import re\n",
        "\n",
        "from sklearn.preprocessing import LabelEncoder\n",
        "\n",
        "data = pd.read_csv('drive/MyDrive/Colab Notebooks/DataSets/Sentiment.csv')\n",
        "# Keeping only the neccessary columns\n",
        "data = data[['text','sentiment']]\n",
        "\n",
        "data['text'] = data['text'].apply(lambda x: x.lower())\n",
        "data['text'] = data['text'].apply((lambda x: re.sub('[^a-zA-z0-9\\s]', '', x)))\n",
        "\n",
        "for idx, row in data.iterrows():\n",
        "    row[0] = row[0].replace('rt', ' ')\n",
        "\n",
        "max_fatures = 2000\n",
        "tokenizer = Tokenizer(num_words=max_fatures, split=' ')\n",
        "tokenizer.fit_on_texts(data['text'].values)\n",
        "X = tokenizer.texts_to_sequences(data['text'].values)\n",
        "\n",
        "X = pad_sequences(X)\n",
        "\n",
        "def createmodel(embed_dim=128, lstm_out=196):\n",
        "    model = Sequential()\n",
        "    model.add(Embedding(max_fatures, embed_dim,input_length = X.shape[1]))\n",
        "    model.add(LSTM(lstm_out, dropout=0.2, recurrent_dropout=0.2))\n",
        "    model.add(Dense(3,activation='softmax'))\n",
        "    model.compile(loss = 'categorical_crossentropy', optimizer='adam',metrics = ['accuracy'])\n",
        "    return model\n",
        "# print(model.summary())\n",
        "\n",
        "labelencoder = LabelEncoder()\n",
        "integer_encoded = labelencoder.fit_transform(data['sentiment'])\n",
        "y = to_categorical(integer_encoded)\n",
        "X_train, X_test, Y_train, Y_test = train_test_split(X,y, test_size = 0.33, random_state = 42)\n",
        "\n",
        "model = KerasClassifier(build_fn=createmodel, verbose=0, embed_dim=128, lstm_out=196)\n",
        "# model = createmodel(\n",
        "param_grid = {\n",
        "    'batch_size': [16, 32, 64],\n",
        "    'epochs': [1, 2, 3],\n",
        "    'embed_dim': [128],\n",
        "    'lstm_out': [196]\n",
        "}\n",
        "grid = GridSearchCV(estimator=model, param_grid=param_grid, cv=3, verbose=1)\n",
        "grid_result = grid.fit(X_train, Y_train)\n",
        "\n",
        "print(\"Best: %f using %s\" % (grid_result.best_score_, grid_result.best_params_))\n",
        "print(score)\n",
        "print(acc)\n",
        "print(model.metrics_names)\n",
        "# Save the best model\n",
        "best_model = grid_result.best_estimator_.model\n",
        "best_model.save('sentiment.h5')\n"
      ]
    },
    {
      "cell_type": "code",
      "source": [
        "from keras.models import load_model\n",
        "model1 = load_model('sentiment.h5')\n",
        "x = tokenizer.texts_to_sequences([\"A lot of good things are happening. We are respected again throughout the world, and that's a great thing.@realDonaldTrump\"])\n",
        "x = pad_sequences(x, maxlen=28)\n",
        "model1.predict(x)"
      ],
      "metadata": {
        "colab": {
          "base_uri": "https://localhost:8080/"
        },
        "id": "ychrh-JE7oA3",
        "outputId": "ca461593-89bf-47ef-dd3d-8f1911f19b43"
      },
      "execution_count": null,
      "outputs": [
        {
          "output_type": "stream",
          "name": "stderr",
          "text": [
            "WARNING:absl:Compiled the loaded model, but the compiled metrics have yet to be built. `model.compile_metrics` will be empty until you train or evaluate the model.\n"
          ]
        },
        {
          "output_type": "stream",
          "name": "stdout",
          "text": [
            "\u001b[1m1/1\u001b[0m \u001b[32m━━━━━━━━━━━━━━━━━━━━\u001b[0m\u001b[37m\u001b[0m \u001b[1m0s\u001b[0m 203ms/step\n"
          ]
        },
        {
          "output_type": "execute_result",
          "data": {
            "text/plain": [
              "array([[0.49588552, 0.20981357, 0.29430088]], dtype=float32)"
            ]
          },
          "metadata": {},
          "execution_count": 26
        }
      ]
    }
  ]
}